================================================================================
load pg_denormalized
================================================================================
invalid socket
invalid socket
invalid socket
server closed the connection unexpectedly
	This probably means the server terminated abnormally
	before or while processing the request.
invalid socket
server closed the connection unexpectedly
	This probably means the server terminated abnormally
	before or while processing the request.
server closed the connection unexpectedly
	This probably means the server terminated abnormally
	before or while processing the request.
server closed the connection unexpectedly
	This probably means the server terminated abnormally
	before or while processing the request.
server closed the connection unexpectedly
	This probably means the server terminated abnormally
	before or while processing the request.
server closed the connection unexpectedly
	This probably means the server terminated abnormally
	before or while processing the request.
Command exited with non-zero status 10
13.50user 3.46system 6:15.83elapsed 4%CPU (0avgtext+0avgdata 17800maxresident)k
24inputs+10816outputs (0major+52857minor)pagefaults 0swaps
================================================================================
load pg_normalized_batch
================================================================================
Traceback (most recent call last):
  File "/home/Liann.Bielicki.24/.local/lib/python3.6/site-packages/sqlalchemy/engine/base.py", line 3371, in _wrap_pool_connect
    return fn()
  File "/home/Liann.Bielicki.24/.local/lib/python3.6/site-packages/sqlalchemy/pool/base.py", line 327, in connect
    return _ConnectionFairy._checkout(self)
  File "/home/Liann.Bielicki.24/.local/lib/python3.6/site-packages/sqlalchemy/pool/base.py", line 894, in _checkout
    fairy = _ConnectionRecord.checkout(pool)
  File "/home/Liann.Bielicki.24/.local/lib/python3.6/site-packages/sqlalchemy/pool/base.py", line 493, in checkout
    rec = pool._do_get()
  File "/home/Liann.Bielicki.24/.local/lib/python3.6/site-packages/sqlalchemy/pool/impl.py", line 146, in _do_get
    self._dec_overflow()
  File "/home/Liann.Bielicki.24/.local/lib/python3.6/site-packages/sqlalchemy/util/langhelpers.py", line 72, in __exit__
    with_traceback=exc_tb,
  File "/home/Liann.Bielicki.24/.local/lib/python3.6/site-packages/sqlalchemy/util/compat.py", line 211, in raise_
    raise exception
  File "/home/Liann.Bielicki.24/.local/lib/python3.6/site-packages/sqlalchemy/pool/impl.py", line 143, in _do_get
    return self._create_connection()
  File "/home/Liann.Bielicki.24/.local/lib/python3.6/site-packages/sqlalchemy/pool/base.py", line 273, in _create_connection
    return _ConnectionRecord(self)
  File "/home/Liann.Bielicki.24/.local/lib/python3.6/site-packages/sqlalchemy/pool/base.py", line 388, in __init__
    self.__connect()
  File "/home/Liann.Bielicki.24/.local/lib/python3.6/site-packages/sqlalchemy/pool/base.py", line 691, in __connect
    pool.logger.debug("Error on connect(): %s", e)
  File "/home/Liann.Bielicki.24/.local/lib/python3.6/site-packages/sqlalchemy/util/langhelpers.py", line 72, in __exit__
    with_traceback=exc_tb,
  File "/home/Liann.Bielicki.24/.local/lib/python3.6/site-packages/sqlalchemy/util/compat.py", line 211, in raise_
    raise exception
  File "/home/Liann.Bielicki.24/.local/lib/python3.6/site-packages/sqlalchemy/pool/base.py", line 686, in __connect
    self.dbapi_connection = connection = pool._invoke_creator(self)
  File "/home/Liann.Bielicki.24/.local/lib/python3.6/site-packages/sqlalchemy/engine/create.py", line 574, in connect
    return dialect.connect(*cargs, **cparams)
  File "/home/Liann.Bielicki.24/.local/lib/python3.6/site-packages/sqlalchemy/engine/default.py", line 598, in connect
    return self.dbapi.connect(*cargs, **cparams)
  File "/home/Liann.Bielicki.24/.local/lib/python3.6/site-packages/psycopg2/__init__.py", line 122, in connect
    conn = _connect(dsn, connection_factory=connection_factory, **kwasync)
psycopg2.OperationalError: could not connect to server: Connection refused
	Is the server running on host "localhost" (127.0.0.1) and accepting
	TCP/IP connections on port 18438?


The above exception was the direct cause of the following exception:

Traceback (most recent call last):
  File "load_tweets_batch.py", line 414, in <module>
    connection = engine.connect()
  File "/home/Liann.Bielicki.24/.local/lib/python3.6/site-packages/sqlalchemy/engine/base.py", line 3325, in connect
    return self._connection_cls(self, close_with_result=close_with_result)
  File "/home/Liann.Bielicki.24/.local/lib/python3.6/site-packages/sqlalchemy/engine/base.py", line 96, in __init__
    else engine.raw_connection()
  File "/home/Liann.Bielicki.24/.local/lib/python3.6/site-packages/sqlalchemy/engine/base.py", line 3404, in raw_connection
    return self._wrap_pool_connect(self.pool.connect, _connection)
  File "/home/Liann.Bielicki.24/.local/lib/python3.6/site-packages/sqlalchemy/engine/base.py", line 3375, in _wrap_pool_connect
    e, dialect, self
  File "/home/Liann.Bielicki.24/.local/lib/python3.6/site-packages/sqlalchemy/engine/base.py", line 2209, in _handle_dbapi_exception_noconnection
    sqlalchemy_exception, with_traceback=exc_info[2], from_=e
  File "/home/Liann.Bielicki.24/.local/lib/python3.6/site-packages/sqlalchemy/util/compat.py", line 211, in raise_
    raise exception
  File "/home/Liann.Bielicki.24/.local/lib/python3.6/site-packages/sqlalchemy/engine/base.py", line 3371, in _wrap_pool_connect
    return fn()
  File "/home/Liann.Bielicki.24/.local/lib/python3.6/site-packages/sqlalchemy/pool/base.py", line 327, in connect
    return _ConnectionFairy._checkout(self)
  File "/home/Liann.Bielicki.24/.local/lib/python3.6/site-packages/sqlalchemy/pool/base.py", line 894, in _checkout
    fairy = _ConnectionRecord.checkout(pool)
  File "/home/Liann.Bielicki.24/.local/lib/python3.6/site-packages/sqlalchemy/pool/base.py", line 493, in checkout
    rec = pool._do_get()
  File "/home/Liann.Bielicki.24/.local/lib/python3.6/site-packages/sqlalchemy/pool/impl.py", line 146, in _do_get
    self._dec_overflow()
  File "/home/Liann.Bielicki.24/.local/lib/python3.6/site-packages/sqlalchemy/util/langhelpers.py", line 72, in __exit__
    with_traceback=exc_tb,
  File "/home/Liann.Bielicki.24/.local/lib/python3.6/site-packages/sqlalchemy/util/compat.py", line 211, in raise_
    raise exception
  File "/home/Liann.Bielicki.24/.local/lib/python3.6/site-packages/sqlalchemy/pool/impl.py", line 143, in _do_get
    return self._create_connection()
  File "/home/Liann.Bielicki.24/.local/lib/python3.6/site-packages/sqlalchemy/pool/base.py", line 273, in _create_connection
    return _ConnectionRecord(self)
  File "/home/Liann.Bielicki.24/.local/lib/python3.6/site-packages/sqlalchemy/pool/base.py", line 388, in __init__
    self.__connect()
  File "/home/Liann.Bielicki.24/.local/lib/python3.6/site-packages/sqlalchemy/pool/base.py", line 691, in __connect
    pool.logger.debug("Error on connect(): %s", e)
  File "/home/Liann.Bielicki.24/.local/lib/python3.6/site-packages/sqlalchemy/util/langhelpers.py", line 72, in __exit__
    with_traceback=exc_tb,
  File "/home/Liann.Bielicki.24/.local/lib/python3.6/site-packages/sqlalchemy/util/compat.py", line 211, in raise_
    raise exception
  File "/home/Liann.Bielicki.24/.local/lib/python3.6/site-packages/sqlalchemy/pool/base.py", line 686, in __connect
    self.dbapi_connection = connection = pool._invoke_creator(self)
  File "/home/Liann.Bielicki.24/.local/lib/python3.6/site-packages/sqlalchemy/engine/create.py", line 574, in connect
    return dialect.connect(*cargs, **cparams)
  File "/home/Liann.Bielicki.24/.local/lib/python3.6/site-packages/sqlalchemy/engine/default.py", line 598, in connect
    return self.dbapi.connect(*cargs, **cparams)
  File "/home/Liann.Bielicki.24/.local/lib/python3.6/site-packages/psycopg2/__init__.py", line 122, in connect
    conn = _connect(dsn, connection_factory=connection_factory, **kwasync)
sqlalchemy.exc.OperationalError: (psycopg2.OperationalError) could not connect to server: Connection refused
	Is the server running on host "localhost" (127.0.0.1) and accepting
	TCP/IP connections on port 18438?

(Background on this error at: https://sqlalche.me/e/14/e3q8)
Traceback (most recent call last):
  File "/home/Liann.Bielicki.24/.local/lib/python3.6/site-packages/sqlalchemy/engine/base.py", line 3371, in _wrap_pool_connect
    return fn()
  File "/home/Liann.Bielicki.24/.local/lib/python3.6/site-packages/sqlalchemy/pool/base.py", line 327, in connect
    return _ConnectionFairy._checkout(self)
  File "/home/Liann.Bielicki.24/.local/lib/python3.6/site-packages/sqlalchemy/pool/base.py", line 894, in _checkout
    fairy = _ConnectionRecord.checkout(pool)
  File "/home/Liann.Bielicki.24/.local/lib/python3.6/site-packages/sqlalchemy/pool/base.py", line 493, in checkout
    rec = pool._do_get()
  File "/home/Liann.Bielicki.24/.local/lib/python3.6/site-packages/sqlalchemy/pool/impl.py", line 146, in _do_get
    self._dec_overflow()
  File "/home/Liann.Bielicki.24/.local/lib/python3.6/site-packages/sqlalchemy/util/langhelpers.py", line 72, in __exit__
    with_traceback=exc_tb,
  File "/home/Liann.Bielicki.24/.local/lib/python3.6/site-packages/sqlalchemy/util/compat.py", line 211, in raise_
    raise exception
  File "/home/Liann.Bielicki.24/.local/lib/python3.6/site-packages/sqlalchemy/pool/impl.py", line 143, in _do_get
    return self._create_connection()
  File "/home/Liann.Bielicki.24/.local/lib/python3.6/site-packages/sqlalchemy/pool/base.py", line 273, in _create_connection
    return _ConnectionRecord(self)
  File "/home/Liann.Bielicki.24/.local/lib/python3.6/site-packages/sqlalchemy/pool/base.py", line 388, in __init__
    self.__connect()
  File "/home/Liann.Bielicki.24/.local/lib/python3.6/site-packages/sqlalchemy/pool/base.py", line 691, in __connect
    pool.logger.debug("Error on connect(): %s", e)
  File "/home/Liann.Bielicki.24/.local/lib/python3.6/site-packages/sqlalchemy/util/langhelpers.py", line 72, in __exit__
    with_traceback=exc_tb,
  File "/home/Liann.Bielicki.24/.local/lib/python3.6/site-packages/sqlalchemy/util/compat.py", line 211, in raise_
    raise exception
  File "/home/Liann.Bielicki.24/.local/lib/python3.6/site-packages/sqlalchemy/pool/base.py", line 686, in __connect
    self.dbapi_connection = connection = pool._invoke_creator(self)
  File "/home/Liann.Bielicki.24/.local/lib/python3.6/site-packages/sqlalchemy/engine/create.py", line 574, in connect
    return dialect.connect(*cargs, **cparams)
  File "/home/Liann.Bielicki.24/.local/lib/python3.6/site-packages/sqlalchemy/engine/default.py", line 598, in connect
    return self.dbapi.connect(*cargs, **cparams)
  File "/home/Liann.Bielicki.24/.local/lib/python3.6/site-packages/psycopg2/__init__.py", line 122, in connect
    conn = _connect(dsn, connection_factory=connection_factory, **kwasync)
psycopg2.OperationalError: could not connect to server: Connection refused
	Is the server running on host "localhost" (127.0.0.1) and accepting
	TCP/IP connections on port 18438?


The above exception was the direct cause of the following exception:

Traceback (most recent call last):
  File "load_tweets_batch.py", line 414, in <module>
    connection = engine.connect()
  File "/home/Liann.Bielicki.24/.local/lib/python3.6/site-packages/sqlalchemy/engine/base.py", line 3325, in connect
    return self._connection_cls(self, close_with_result=close_with_result)
  File "/home/Liann.Bielicki.24/.local/lib/python3.6/site-packages/sqlalchemy/engine/base.py", line 96, in __init__
    else engine.raw_connection()
  File "/home/Liann.Bielicki.24/.local/lib/python3.6/site-packages/sqlalchemy/engine/base.py", line 3404, in raw_connection
    return self._wrap_pool_connect(self.pool.connect, _connection)
  File "/home/Liann.Bielicki.24/.local/lib/python3.6/site-packages/sqlalchemy/engine/base.py", line 3375, in _wrap_pool_connect
    e, dialect, self
  File "/home/Liann.Bielicki.24/.local/lib/python3.6/site-packages/sqlalchemy/engine/base.py", line 2209, in _handle_dbapi_exception_noconnection
    sqlalchemy_exception, with_traceback=exc_info[2], from_=e
  File "/home/Liann.Bielicki.24/.local/lib/python3.6/site-packages/sqlalchemy/util/compat.py", line 211, in raise_
    raise exception
  File "/home/Liann.Bielicki.24/.local/lib/python3.6/site-packages/sqlalchemy/engine/base.py", line 3371, in _wrap_pool_connect
    return fn()
  File "/home/Liann.Bielicki.24/.local/lib/python3.6/site-packages/sqlalchemy/pool/base.py", line 327, in connect
    return _ConnectionFairy._checkout(self)
  File "/home/Liann.Bielicki.24/.local/lib/python3.6/site-packages/sqlalchemy/pool/base.py", line 894, in _checkout
    fairy = _ConnectionRecord.checkout(pool)
  File "/home/Liann.Bielicki.24/.local/lib/python3.6/site-packages/sqlalchemy/pool/base.py", line 493, in checkout
    rec = pool._do_get()
  File "/home/Liann.Bielicki.24/.local/lib/python3.6/site-packages/sqlalchemy/pool/impl.py", line 146, in _do_get
    self._dec_overflow()
  File "/home/Liann.Bielicki.24/.local/lib/python3.6/site-packages/sqlalchemy/util/langhelpers.py", line 72, in __exit__
    with_traceback=exc_tb,
  File "/home/Liann.Bielicki.24/.local/lib/python3.6/site-packages/sqlalchemy/util/compat.py", line 211, in raise_
    raise exception
  File "/home/Liann.Bielicki.24/.local/lib/python3.6/site-packages/sqlalchemy/pool/impl.py", line 143, in _do_get
    return self._create_connection()
  File "/home/Liann.Bielicki.24/.local/lib/python3.6/site-packages/sqlalchemy/pool/base.py", line 273, in _create_connection
    return _ConnectionRecord(self)
  File "/home/Liann.Bielicki.24/.local/lib/python3.6/site-packages/sqlalchemy/pool/base.py", line 388, in __init__
    self.__connect()
  File "/home/Liann.Bielicki.24/.local/lib/python3.6/site-packages/sqlalchemy/pool/base.py", line 691, in __connect
    pool.logger.debug("Error on connect(): %s", e)
  File "/home/Liann.Bielicki.24/.local/lib/python3.6/site-packages/sqlalchemy/util/langhelpers.py", line 72, in __exit__
    with_traceback=exc_tb,
  File "/home/Liann.Bielicki.24/.local/lib/python3.6/site-packages/sqlalchemy/util/compat.py", line 211, in raise_
    raise exception
  File "/home/Liann.Bielicki.24/.local/lib/python3.6/site-packages/sqlalchemy/pool/base.py", line 686, in __connect
    self.dbapi_connection = connection = pool._invoke_creator(self)
  File "/home/Liann.Bielicki.24/.local/lib/python3.6/site-packages/sqlalchemy/engine/create.py", line 574, in connect
    return dialect.connect(*cargs, **cparams)
  File "/home/Liann.Bielicki.24/.local/lib/python3.6/site-packages/sqlalchemy/engine/default.py", line 598, in connect
    return self.dbapi.connect(*cargs, **cparams)
  File "/home/Liann.Bielicki.24/.local/lib/python3.6/site-packages/psycopg2/__init__.py", line 122, in connect
    conn = _connect(dsn, connection_factory=connection_factory, **kwasync)
sqlalchemy.exc.OperationalError: (psycopg2.OperationalError) could not connect to server: Connection refused
	Is the server running on host "localhost" (127.0.0.1) and accepting
	TCP/IP connections on port 18438?

(Background on this error at: https://sqlalche.me/e/14/e3q8)
Traceback (most recent call last):
  File "/home/Liann.Bielicki.24/.local/lib/python3.6/site-packages/sqlalchemy/engine/base.py", line 3371, in _wrap_pool_connect
    return fn()
  File "/home/Liann.Bielicki.24/.local/lib/python3.6/site-packages/sqlalchemy/pool/base.py", line 327, in connect
    return _ConnectionFairy._checkout(self)
  File "/home/Liann.Bielicki.24/.local/lib/python3.6/site-packages/sqlalchemy/pool/base.py", line 894, in _checkout
    fairy = _ConnectionRecord.checkout(pool)
  File "/home/Liann.Bielicki.24/.local/lib/python3.6/site-packages/sqlalchemy/pool/base.py", line 493, in checkout
    rec = pool._do_get()
  File "/home/Liann.Bielicki.24/.local/lib/python3.6/site-packages/sqlalchemy/pool/impl.py", line 146, in _do_get
    self._dec_overflow()
  File "/home/Liann.Bielicki.24/.local/lib/python3.6/site-packages/sqlalchemy/util/langhelpers.py", line 72, in __exit__
    with_traceback=exc_tb,
  File "/home/Liann.Bielicki.24/.local/lib/python3.6/site-packages/sqlalchemy/util/compat.py", line 211, in raise_
    raise exception
  File "/home/Liann.Bielicki.24/.local/lib/python3.6/site-packages/sqlalchemy/pool/impl.py", line 143, in _do_get
    return self._create_connection()
  File "/home/Liann.Bielicki.24/.local/lib/python3.6/site-packages/sqlalchemy/pool/base.py", line 273, in _create_connection
    return _ConnectionRecord(self)
  File "/home/Liann.Bielicki.24/.local/lib/python3.6/site-packages/sqlalchemy/pool/base.py", line 388, in __init__
    self.__connect()
  File "/home/Liann.Bielicki.24/.local/lib/python3.6/site-packages/sqlalchemy/pool/base.py", line 691, in __connect
    pool.logger.debug("Error on connect(): %s", e)
  File "/home/Liann.Bielicki.24/.local/lib/python3.6/site-packages/sqlalchemy/util/langhelpers.py", line 72, in __exit__
    with_traceback=exc_tb,
  File "/home/Liann.Bielicki.24/.local/lib/python3.6/site-packages/sqlalchemy/util/compat.py", line 211, in raise_
    raise exception
  File "/home/Liann.Bielicki.24/.local/lib/python3.6/site-packages/sqlalchemy/pool/base.py", line 686, in __connect
    self.dbapi_connection = connection = pool._invoke_creator(self)
  File "/home/Liann.Bielicki.24/.local/lib/python3.6/site-packages/sqlalchemy/engine/create.py", line 574, in connect
    return dialect.connect(*cargs, **cparams)
  File "/home/Liann.Bielicki.24/.local/lib/python3.6/site-packages/sqlalchemy/engine/default.py", line 598, in connect
    return self.dbapi.connect(*cargs, **cparams)
  File "/home/Liann.Bielicki.24/.local/lib/python3.6/site-packages/psycopg2/__init__.py", line 122, in connect
    conn = _connect(dsn, connection_factory=connection_factory, **kwasync)
psycopg2.OperationalError: could not connect to server: Connection refused
	Is the server running on host "localhost" (127.0.0.1) and accepting
	TCP/IP connections on port 18438?


The above exception was the direct cause of the following exception:

Traceback (most recent call last):
  File "load_tweets_batch.py", line 414, in <module>
    connection = engine.connect()
  File "/home/Liann.Bielicki.24/.local/lib/python3.6/site-packages/sqlalchemy/engine/base.py", line 3325, in connect
    return self._connection_cls(self, close_with_result=close_with_result)
  File "/home/Liann.Bielicki.24/.local/lib/python3.6/site-packages/sqlalchemy/engine/base.py", line 96, in __init__
    else engine.raw_connection()
  File "/home/Liann.Bielicki.24/.local/lib/python3.6/site-packages/sqlalchemy/engine/base.py", line 3404, in raw_connection
    return self._wrap_pool_connect(self.pool.connect, _connection)
  File "/home/Liann.Bielicki.24/.local/lib/python3.6/site-packages/sqlalchemy/engine/base.py", line 3375, in _wrap_pool_connect
    e, dialect, self
  File "/home/Liann.Bielicki.24/.local/lib/python3.6/site-packages/sqlalchemy/engine/base.py", line 2209, in _handle_dbapi_exception_noconnection
    sqlalchemy_exception, with_traceback=exc_info[2], from_=e
  File "/home/Liann.Bielicki.24/.local/lib/python3.6/site-packages/sqlalchemy/util/compat.py", line 211, in raise_
    raise exception
  File "/home/Liann.Bielicki.24/.local/lib/python3.6/site-packages/sqlalchemy/engine/base.py", line 3371, in _wrap_pool_connect
    return fn()
  File "/home/Liann.Bielicki.24/.local/lib/python3.6/site-packages/sqlalchemy/pool/base.py", line 327, in connect
    return _ConnectionFairy._checkout(self)
  File "/home/Liann.Bielicki.24/.local/lib/python3.6/site-packages/sqlalchemy/pool/base.py", line 894, in _checkout
    fairy = _ConnectionRecord.checkout(pool)
  File "/home/Liann.Bielicki.24/.local/lib/python3.6/site-packages/sqlalchemy/pool/base.py", line 493, in checkout
    rec = pool._do_get()
  File "/home/Liann.Bielicki.24/.local/lib/python3.6/site-packages/sqlalchemy/pool/impl.py", line 146, in _do_get
    self._dec_overflow()
  File "/home/Liann.Bielicki.24/.local/lib/python3.6/site-packages/sqlalchemy/util/langhelpers.py", line 72, in __exit__
    with_traceback=exc_tb,
  File "/home/Liann.Bielicki.24/.local/lib/python3.6/site-packages/sqlalchemy/util/compat.py", line 211, in raise_
    raise exception
  File "/home/Liann.Bielicki.24/.local/lib/python3.6/site-packages/sqlalchemy/pool/impl.py", line 143, in _do_get
    return self._create_connection()
  File "/home/Liann.Bielicki.24/.local/lib/python3.6/site-packages/sqlalchemy/pool/base.py", line 273, in _create_connection
    return _ConnectionRecord(self)
  File "/home/Liann.Bielicki.24/.local/lib/python3.6/site-packages/sqlalchemy/pool/base.py", line 388, in __init__
    self.__connect()
  File "/home/Liann.Bielicki.24/.local/lib/python3.6/site-packages/sqlalchemy/pool/base.py", line 691, in __connect
    pool.logger.debug("Error on connect(): %s", e)
  File "/home/Liann.Bielicki.24/.local/lib/python3.6/site-packages/sqlalchemy/util/langhelpers.py", line 72, in __exit__
    with_traceback=exc_tb,
  File "/home/Liann.Bielicki.24/.local/lib/python3.6/site-packages/sqlalchemy/util/compat.py", line 211, in raise_
    raise exception
  File "/home/Liann.Bielicki.24/.local/lib/python3.6/site-packages/sqlalchemy/pool/base.py", line 686, in __connect
    self.dbapi_connection = connection = pool._invoke_creator(self)
  File "/home/Liann.Bielicki.24/.local/lib/python3.6/site-packages/sqlalchemy/engine/create.py", line 574, in connect
    return dialect.connect(*cargs, **cparams)
  File "/home/Liann.Bielicki.24/.local/lib/python3.6/site-packages/sqlalchemy/engine/default.py", line 598, in connect
    return self.dbapi.connect(*cargs, **cparams)
  File "/home/Liann.Bielicki.24/.local/lib/python3.6/site-packages/psycopg2/__init__.py", line 122, in connect
    conn = _connect(dsn, connection_factory=connection_factory, **kwasync)
sqlalchemy.exc.OperationalError: (psycopg2.OperationalError) could not connect to server: Connection refused
	Is the server running on host "localhost" (127.0.0.1) and accepting
	TCP/IP connections on port 18438?

(Background on this error at: https://sqlalche.me/e/14/e3q8)
Traceback (most recent call last):
  File "/home/Liann.Bielicki.24/.local/lib/python3.6/site-packages/sqlalchemy/engine/base.py", line 3371, in _wrap_pool_connect
    return fn()
  File "/home/Liann.Bielicki.24/.local/lib/python3.6/site-packages/sqlalchemy/pool/base.py", line 327, in connect
    return _ConnectionFairy._checkout(self)
  File "/home/Liann.Bielicki.24/.local/lib/python3.6/site-packages/sqlalchemy/pool/base.py", line 894, in _checkout
    fairy = _ConnectionRecord.checkout(pool)
  File "/home/Liann.Bielicki.24/.local/lib/python3.6/site-packages/sqlalchemy/pool/base.py", line 493, in checkout
    rec = pool._do_get()
  File "/home/Liann.Bielicki.24/.local/lib/python3.6/site-packages/sqlalchemy/pool/impl.py", line 146, in _do_get
    self._dec_overflow()
  File "/home/Liann.Bielicki.24/.local/lib/python3.6/site-packages/sqlalchemy/util/langhelpers.py", line 72, in __exit__
    with_traceback=exc_tb,
  File "/home/Liann.Bielicki.24/.local/lib/python3.6/site-packages/sqlalchemy/util/compat.py", line 211, in raise_
    raise exception
  File "/home/Liann.Bielicki.24/.local/lib/python3.6/site-packages/sqlalchemy/pool/impl.py", line 143, in _do_get
    return self._create_connection()
  File "/home/Liann.Bielicki.24/.local/lib/python3.6/site-packages/sqlalchemy/pool/base.py", line 273, in _create_connection
    return _ConnectionRecord(self)
  File "/home/Liann.Bielicki.24/.local/lib/python3.6/site-packages/sqlalchemy/pool/base.py", line 388, in __init__
    self.__connect()
  File "/home/Liann.Bielicki.24/.local/lib/python3.6/site-packages/sqlalchemy/pool/base.py", line 691, in __connect
    pool.logger.debug("Error on connect(): %s", e)
  File "/home/Liann.Bielicki.24/.local/lib/python3.6/site-packages/sqlalchemy/util/langhelpers.py", line 72, in __exit__
    with_traceback=exc_tb,
  File "/home/Liann.Bielicki.24/.local/lib/python3.6/site-packages/sqlalchemy/util/compat.py", line 211, in raise_
    raise exception
  File "/home/Liann.Bielicki.24/.local/lib/python3.6/site-packages/sqlalchemy/pool/base.py", line 686, in __connect
    self.dbapi_connection = connection = pool._invoke_creator(self)
  File "/home/Liann.Bielicki.24/.local/lib/python3.6/site-packages/sqlalchemy/engine/create.py", line 574, in connect
    return dialect.connect(*cargs, **cparams)
  File "/home/Liann.Bielicki.24/.local/lib/python3.6/site-packages/sqlalchemy/engine/default.py", line 598, in connect
    return self.dbapi.connect(*cargs, **cparams)
  File "/home/Liann.Bielicki.24/.local/lib/python3.6/site-packages/psycopg2/__init__.py", line 122, in connect
    conn = _connect(dsn, connection_factory=connection_factory, **kwasync)
psycopg2.OperationalError: could not connect to server: Connection refused
	Is the server running on host "localhost" (127.0.0.1) and accepting
	TCP/IP connections on port 18438?


The above exception was the direct cause of the following exception:

Traceback (most recent call last):
  File "load_tweets_batch.py", line 414, in <module>
    connection = engine.connect()
  File "/home/Liann.Bielicki.24/.local/lib/python3.6/site-packages/sqlalchemy/engine/base.py", line 3325, in connect
    return self._connection_cls(self, close_with_result=close_with_result)
  File "/home/Liann.Bielicki.24/.local/lib/python3.6/site-packages/sqlalchemy/engine/base.py", line 96, in __init__
    else engine.raw_connection()
  File "/home/Liann.Bielicki.24/.local/lib/python3.6/site-packages/sqlalchemy/engine/base.py", line 3404, in raw_connection
    return self._wrap_pool_connect(self.pool.connect, _connection)
  File "/home/Liann.Bielicki.24/.local/lib/python3.6/site-packages/sqlalchemy/engine/base.py", line 3375, in _wrap_pool_connect
    e, dialect, self
  File "/home/Liann.Bielicki.24/.local/lib/python3.6/site-packages/sqlalchemy/engine/base.py", line 2209, in _handle_dbapi_exception_noconnection
    sqlalchemy_exception, with_traceback=exc_info[2], from_=e
  File "/home/Liann.Bielicki.24/.local/lib/python3.6/site-packages/sqlalchemy/util/compat.py", line 211, in raise_
    raise exception
  File "/home/Liann.Bielicki.24/.local/lib/python3.6/site-packages/sqlalchemy/engine/base.py", line 3371, in _wrap_pool_connect
    return fn()
  File "/home/Liann.Bielicki.24/.local/lib/python3.6/site-packages/sqlalchemy/pool/base.py", line 327, in connect
    return _ConnectionFairy._checkout(self)
  File "/home/Liann.Bielicki.24/.local/lib/python3.6/site-packages/sqlalchemy/pool/base.py", line 894, in _checkout
    fairy = _ConnectionRecord.checkout(pool)
  File "/home/Liann.Bielicki.24/.local/lib/python3.6/site-packages/sqlalchemy/pool/base.py", line 493, in checkout
    rec = pool._do_get()
  File "/home/Liann.Bielicki.24/.local/lib/python3.6/site-packages/sqlalchemy/pool/impl.py", line 146, in _do_get
    self._dec_overflow()
  File "/home/Liann.Bielicki.24/.local/lib/python3.6/site-packages/sqlalchemy/util/langhelpers.py", line 72, in __exit__
    with_traceback=exc_tb,
  File "/home/Liann.Bielicki.24/.local/lib/python3.6/site-packages/sqlalchemy/util/compat.py", line 211, in raise_
    raise exception
  File "/home/Liann.Bielicki.24/.local/lib/python3.6/site-packages/sqlalchemy/pool/impl.py", line 143, in _do_get
    return self._create_connection()
  File "/home/Liann.Bielicki.24/.local/lib/python3.6/site-packages/sqlalchemy/pool/base.py", line 273, in _create_connection
    return _ConnectionRecord(self)
  File "/home/Liann.Bielicki.24/.local/lib/python3.6/site-packages/sqlalchemy/pool/base.py", line 388, in __init__
    self.__connect()
  File "/home/Liann.Bielicki.24/.local/lib/python3.6/site-packages/sqlalchemy/pool/base.py", line 691, in __connect
    pool.logger.debug("Error on connect(): %s", e)
  File "/home/Liann.Bielicki.24/.local/lib/python3.6/site-packages/sqlalchemy/util/langhelpers.py", line 72, in __exit__
    with_traceback=exc_tb,
  File "/home/Liann.Bielicki.24/.local/lib/python3.6/site-packages/sqlalchemy/util/compat.py", line 211, in raise_
    raise exception
  File "/home/Liann.Bielicki.24/.local/lib/python3.6/site-packages/sqlalchemy/pool/base.py", line 686, in __connect
    self.dbapi_connection = connection = pool._invoke_creator(self)
  File "/home/Liann.Bielicki.24/.local/lib/python3.6/site-packages/sqlalchemy/engine/create.py", line 574, in connect
    return dialect.connect(*cargs, **cparams)
  File "/home/Liann.Bielicki.24/.local/lib/python3.6/site-packages/sqlalchemy/engine/default.py", line 598, in connect
    return self.dbapi.connect(*cargs, **cparams)
  File "/home/Liann.Bielicki.24/.local/lib/python3.6/site-packages/psycopg2/__init__.py", line 122, in connect
    conn = _connect(dsn, connection_factory=connection_factory, **kwasync)
sqlalchemy.exc.OperationalError: (psycopg2.OperationalError) could not connect to server: Connection refused
	Is the server running on host "localhost" (127.0.0.1) and accepting
	TCP/IP connections on port 18438?

(Background on this error at: https://sqlalche.me/e/14/e3q8)
Traceback (most recent call last):
  File "/home/Liann.Bielicki.24/.local/lib/python3.6/site-packages/sqlalchemy/engine/base.py", line 3371, in _wrap_pool_connect
    return fn()
  File "/home/Liann.Bielicki.24/.local/lib/python3.6/site-packages/sqlalchemy/pool/base.py", line 327, in connect
    return _ConnectionFairy._checkout(self)
  File "/home/Liann.Bielicki.24/.local/lib/python3.6/site-packages/sqlalchemy/pool/base.py", line 894, in _checkout
    fairy = _ConnectionRecord.checkout(pool)
  File "/home/Liann.Bielicki.24/.local/lib/python3.6/site-packages/sqlalchemy/pool/base.py", line 493, in checkout
    rec = pool._do_get()
  File "/home/Liann.Bielicki.24/.local/lib/python3.6/site-packages/sqlalchemy/pool/impl.py", line 146, in _do_get
    self._dec_overflow()
  File "/home/Liann.Bielicki.24/.local/lib/python3.6/site-packages/sqlalchemy/util/langhelpers.py", line 72, in __exit__
    with_traceback=exc_tb,
  File "/home/Liann.Bielicki.24/.local/lib/python3.6/site-packages/sqlalchemy/util/compat.py", line 211, in raise_
    raise exception
  File "/home/Liann.Bielicki.24/.local/lib/python3.6/site-packages/sqlalchemy/pool/impl.py", line 143, in _do_get
    return self._create_connection()
  File "/home/Liann.Bielicki.24/.local/lib/python3.6/site-packages/sqlalchemy/pool/base.py", line 273, in _create_connection
    return _ConnectionRecord(self)
  File "/home/Liann.Bielicki.24/.local/lib/python3.6/site-packages/sqlalchemy/pool/base.py", line 388, in __init__
    self.__connect()
  File "/home/Liann.Bielicki.24/.local/lib/python3.6/site-packages/sqlalchemy/pool/base.py", line 691, in __connect
    pool.logger.debug("Error on connect(): %s", e)
  File "/home/Liann.Bielicki.24/.local/lib/python3.6/site-packages/sqlalchemy/util/langhelpers.py", line 72, in __exit__
    with_traceback=exc_tb,
  File "/home/Liann.Bielicki.24/.local/lib/python3.6/site-packages/sqlalchemy/util/compat.py", line 211, in raise_
    raise exception
  File "/home/Liann.Bielicki.24/.local/lib/python3.6/site-packages/sqlalchemy/pool/base.py", line 686, in __connect
    self.dbapi_connection = connection = pool._invoke_creator(self)
  File "/home/Liann.Bielicki.24/.local/lib/python3.6/site-packages/sqlalchemy/engine/create.py", line 574, in connect
    return dialect.connect(*cargs, **cparams)
  File "/home/Liann.Bielicki.24/.local/lib/python3.6/site-packages/sqlalchemy/engine/default.py", line 598, in connect
    return self.dbapi.connect(*cargs, **cparams)
  File "/home/Liann.Bielicki.24/.local/lib/python3.6/site-packages/psycopg2/__init__.py", line 122, in connect
    conn = _connect(dsn, connection_factory=connection_factory, **kwasync)
psycopg2.OperationalError: could not connect to server: Connection refused
	Is the server running on host "localhost" (127.0.0.1) and accepting
	TCP/IP connections on port 18438?


The above exception was the direct cause of the following exception:

Traceback (most recent call last):
  File "load_tweets_batch.py", line 414, in <module>
    connection = engine.connect()
  File "/home/Liann.Bielicki.24/.local/lib/python3.6/site-packages/sqlalchemy/engine/base.py", line 3325, in connect
    return self._connection_cls(self, close_with_result=close_with_result)
  File "/home/Liann.Bielicki.24/.local/lib/python3.6/site-packages/sqlalchemy/engine/base.py", line 96, in __init__
    else engine.raw_connection()
  File "/home/Liann.Bielicki.24/.local/lib/python3.6/site-packages/sqlalchemy/engine/base.py", line 3404, in raw_connection
    return self._wrap_pool_connect(self.pool.connect, _connection)
  File "/home/Liann.Bielicki.24/.local/lib/python3.6/site-packages/sqlalchemy/engine/base.py", line 3375, in _wrap_pool_connect
    e, dialect, self
  File "/home/Liann.Bielicki.24/.local/lib/python3.6/site-packages/sqlalchemy/engine/base.py", line 2209, in _handle_dbapi_exception_noconnection
    sqlalchemy_exception, with_traceback=exc_info[2], from_=e
  File "/home/Liann.Bielicki.24/.local/lib/python3.6/site-packages/sqlalchemy/util/compat.py", line 211, in raise_
    raise exception
  File "/home/Liann.Bielicki.24/.local/lib/python3.6/site-packages/sqlalchemy/engine/base.py", line 3371, in _wrap_pool_connect
    return fn()
  File "/home/Liann.Bielicki.24/.local/lib/python3.6/site-packages/sqlalchemy/pool/base.py", line 327, in connect
    return _ConnectionFairy._checkout(self)
  File "/home/Liann.Bielicki.24/.local/lib/python3.6/site-packages/sqlalchemy/pool/base.py", line 894, in _checkout
    fairy = _ConnectionRecord.checkout(pool)
  File "/home/Liann.Bielicki.24/.local/lib/python3.6/site-packages/sqlalchemy/pool/base.py", line 493, in checkout
    rec = pool._do_get()
  File "/home/Liann.Bielicki.24/.local/lib/python3.6/site-packages/sqlalchemy/pool/impl.py", line 146, in _do_get
    self._dec_overflow()
  File "/home/Liann.Bielicki.24/.local/lib/python3.6/site-packages/sqlalchemy/util/langhelpers.py", line 72, in __exit__
    with_traceback=exc_tb,
  File "/home/Liann.Bielicki.24/.local/lib/python3.6/site-packages/sqlalchemy/util/compat.py", line 211, in raise_
    raise exception
  File "/home/Liann.Bielicki.24/.local/lib/python3.6/site-packages/sqlalchemy/pool/impl.py", line 143, in _do_get
    return self._create_connection()
  File "/home/Liann.Bielicki.24/.local/lib/python3.6/site-packages/sqlalchemy/pool/base.py", line 273, in _create_connection
    return _ConnectionRecord(self)
  File "/home/Liann.Bielicki.24/.local/lib/python3.6/site-packages/sqlalchemy/pool/base.py", line 388, in __init__
    self.__connect()
  File "/home/Liann.Bielicki.24/.local/lib/python3.6/site-packages/sqlalchemy/pool/base.py", line 691, in __connect
    pool.logger.debug("Error on connect(): %s", e)
  File "/home/Liann.Bielicki.24/.local/lib/python3.6/site-packages/sqlalchemy/util/langhelpers.py", line 72, in __exit__
    with_traceback=exc_tb,
  File "/home/Liann.Bielicki.24/.local/lib/python3.6/site-packages/sqlalchemy/util/compat.py", line 211, in raise_
    raise exception
  File "/home/Liann.Bielicki.24/.local/lib/python3.6/site-packages/sqlalchemy/pool/base.py", line 686, in __connect
    self.dbapi_connection = connection = pool._invoke_creator(self)
  File "/home/Liann.Bielicki.24/.local/lib/python3.6/site-packages/sqlalchemy/engine/create.py", line 574, in connect
    return dialect.connect(*cargs, **cparams)
  File "/home/Liann.Bielicki.24/.local/lib/python3.6/site-packages/sqlalchemy/engine/default.py", line 598, in connect
    return self.dbapi.connect(*cargs, **cparams)
  File "/home/Liann.Bielicki.24/.local/lib/python3.6/site-packages/psycopg2/__init__.py", line 122, in connect
    conn = _connect(dsn, connection_factory=connection_factory, **kwasync)
sqlalchemy.exc.OperationalError: (psycopg2.OperationalError) could not connect to server: Connection refused
	Is the server running on host "localhost" (127.0.0.1) and accepting
	TCP/IP connections on port 18438?

(Background on this error at: https://sqlalche.me/e/14/e3q8)
Traceback (most recent call last):
  File "/home/Liann.Bielicki.24/.local/lib/python3.6/site-packages/sqlalchemy/engine/base.py", line 3371, in _wrap_pool_connect
    return fn()
  File "/home/Liann.Bielicki.24/.local/lib/python3.6/site-packages/sqlalchemy/pool/base.py", line 327, in connect
    return _ConnectionFairy._checkout(self)
  File "/home/Liann.Bielicki.24/.local/lib/python3.6/site-packages/sqlalchemy/pool/base.py", line 894, in _checkout
    fairy = _ConnectionRecord.checkout(pool)
  File "/home/Liann.Bielicki.24/.local/lib/python3.6/site-packages/sqlalchemy/pool/base.py", line 493, in checkout
    rec = pool._do_get()
  File "/home/Liann.Bielicki.24/.local/lib/python3.6/site-packages/sqlalchemy/pool/impl.py", line 146, in _do_get
    self._dec_overflow()
  File "/home/Liann.Bielicki.24/.local/lib/python3.6/site-packages/sqlalchemy/util/langhelpers.py", line 72, in __exit__
    with_traceback=exc_tb,
  File "/home/Liann.Bielicki.24/.local/lib/python3.6/site-packages/sqlalchemy/util/compat.py", line 211, in raise_
    raise exception
  File "/home/Liann.Bielicki.24/.local/lib/python3.6/site-packages/sqlalchemy/pool/impl.py", line 143, in _do_get
    return self._create_connection()
  File "/home/Liann.Bielicki.24/.local/lib/python3.6/site-packages/sqlalchemy/pool/base.py", line 273, in _create_connection
    return _ConnectionRecord(self)
  File "/home/Liann.Bielicki.24/.local/lib/python3.6/site-packages/sqlalchemy/pool/base.py", line 388, in __init__
    self.__connect()
  File "/home/Liann.Bielicki.24/.local/lib/python3.6/site-packages/sqlalchemy/pool/base.py", line 691, in __connect
    pool.logger.debug("Error on connect(): %s", e)
  File "/home/Liann.Bielicki.24/.local/lib/python3.6/site-packages/sqlalchemy/util/langhelpers.py", line 72, in __exit__
    with_traceback=exc_tb,
  File "/home/Liann.Bielicki.24/.local/lib/python3.6/site-packages/sqlalchemy/util/compat.py", line 211, in raise_
    raise exception
  File "/home/Liann.Bielicki.24/.local/lib/python3.6/site-packages/sqlalchemy/pool/base.py", line 686, in __connect
    self.dbapi_connection = connection = pool._invoke_creator(self)
  File "/home/Liann.Bielicki.24/.local/lib/python3.6/site-packages/sqlalchemy/engine/create.py", line 574, in connect
    return dialect.connect(*cargs, **cparams)
  File "/home/Liann.Bielicki.24/.local/lib/python3.6/site-packages/sqlalchemy/engine/default.py", line 598, in connect
    return self.dbapi.connect(*cargs, **cparams)
  File "/home/Liann.Bielicki.24/.local/lib/python3.6/site-packages/psycopg2/__init__.py", line 122, in connect
    conn = _connect(dsn, connection_factory=connection_factory, **kwasync)
psycopg2.OperationalError: could not connect to server: Connection refused
	Is the server running on host "localhost" (127.0.0.1) and accepting
	TCP/IP connections on port 18438?


The above exception was the direct cause of the following exception:

Traceback (most recent call last):
  File "load_tweets_batch.py", line 414, in <module>
    connection = engine.connect()
  File "/home/Liann.Bielicki.24/.local/lib/python3.6/site-packages/sqlalchemy/engine/base.py", line 3325, in connect
    return self._connection_cls(self, close_with_result=close_with_result)
  File "/home/Liann.Bielicki.24/.local/lib/python3.6/site-packages/sqlalchemy/engine/base.py", line 96, in __init__
    else engine.raw_connection()
  File "/home/Liann.Bielicki.24/.local/lib/python3.6/site-packages/sqlalchemy/engine/base.py", line 3404, in raw_connection
    return self._wrap_pool_connect(self.pool.connect, _connection)
  File "/home/Liann.Bielicki.24/.local/lib/python3.6/site-packages/sqlalchemy/engine/base.py", line 3375, in _wrap_pool_connect
    e, dialect, self
  File "/home/Liann.Bielicki.24/.local/lib/python3.6/site-packages/sqlalchemy/engine/base.py", line 2209, in _handle_dbapi_exception_noconnection
    sqlalchemy_exception, with_traceback=exc_info[2], from_=e
  File "/home/Liann.Bielicki.24/.local/lib/python3.6/site-packages/sqlalchemy/util/compat.py", line 211, in raise_
    raise exception
  File "/home/Liann.Bielicki.24/.local/lib/python3.6/site-packages/sqlalchemy/engine/base.py", line 3371, in _wrap_pool_connect
    return fn()
  File "/home/Liann.Bielicki.24/.local/lib/python3.6/site-packages/sqlalchemy/pool/base.py", line 327, in connect
    return _ConnectionFairy._checkout(self)
  File "/home/Liann.Bielicki.24/.local/lib/python3.6/site-packages/sqlalchemy/pool/base.py", line 894, in _checkout
    fairy = _ConnectionRecord.checkout(pool)
  File "/home/Liann.Bielicki.24/.local/lib/python3.6/site-packages/sqlalchemy/pool/base.py", line 493, in checkout
    rec = pool._do_get()
  File "/home/Liann.Bielicki.24/.local/lib/python3.6/site-packages/sqlalchemy/pool/impl.py", line 146, in _do_get
    self._dec_overflow()
  File "/home/Liann.Bielicki.24/.local/lib/python3.6/site-packages/sqlalchemy/util/langhelpers.py", line 72, in __exit__
    with_traceback=exc_tb,
  File "/home/Liann.Bielicki.24/.local/lib/python3.6/site-packages/sqlalchemy/util/compat.py", line 211, in raise_
    raise exception
  File "/home/Liann.Bielicki.24/.local/lib/python3.6/site-packages/sqlalchemy/pool/impl.py", line 143, in _do_get
    return self._create_connection()
  File "/home/Liann.Bielicki.24/.local/lib/python3.6/site-packages/sqlalchemy/pool/base.py", line 273, in _create_connection
    return _ConnectionRecord(self)
  File "/home/Liann.Bielicki.24/.local/lib/python3.6/site-packages/sqlalchemy/pool/base.py", line 388, in __init__
    self.__connect()
  File "/home/Liann.Bielicki.24/.local/lib/python3.6/site-packages/sqlalchemy/pool/base.py", line 691, in __connect
    pool.logger.debug("Error on connect(): %s", e)
  File "/home/Liann.Bielicki.24/.local/lib/python3.6/site-packages/sqlalchemy/util/langhelpers.py", line 72, in __exit__
    with_traceback=exc_tb,
  File "/home/Liann.Bielicki.24/.local/lib/python3.6/site-packages/sqlalchemy/util/compat.py", line 211, in raise_
    raise exception
  File "/home/Liann.Bielicki.24/.local/lib/python3.6/site-packages/sqlalchemy/pool/base.py", line 686, in __connect
    self.dbapi_connection = connection = pool._invoke_creator(self)
  File "/home/Liann.Bielicki.24/.local/lib/python3.6/site-packages/sqlalchemy/engine/create.py", line 574, in connect
    return dialect.connect(*cargs, **cparams)
  File "/home/Liann.Bielicki.24/.local/lib/python3.6/site-packages/sqlalchemy/engine/default.py", line 598, in connect
    return self.dbapi.connect(*cargs, **cparams)
  File "/home/Liann.Bielicki.24/.local/lib/python3.6/site-packages/psycopg2/__init__.py", line 122, in connect
    conn = _connect(dsn, connection_factory=connection_factory, **kwasync)
sqlalchemy.exc.OperationalError: (psycopg2.OperationalError) could not connect to server: Connection refused
	Is the server running on host "localhost" (127.0.0.1) and accepting
	TCP/IP connections on port 18438?

(Background on this error at: https://sqlalche.me/e/14/e3q8)
Traceback (most recent call last):
  File "/home/Liann.Bielicki.24/.local/lib/python3.6/site-packages/sqlalchemy/engine/base.py", line 3371, in _wrap_pool_connect
    return fn()
  File "/home/Liann.Bielicki.24/.local/lib/python3.6/site-packages/sqlalchemy/pool/base.py", line 327, in connect
    return _ConnectionFairy._checkout(self)
  File "/home/Liann.Bielicki.24/.local/lib/python3.6/site-packages/sqlalchemy/pool/base.py", line 894, in _checkout
    fairy = _ConnectionRecord.checkout(pool)
  File "/home/Liann.Bielicki.24/.local/lib/python3.6/site-packages/sqlalchemy/pool/base.py", line 493, in checkout
    rec = pool._do_get()
  File "/home/Liann.Bielicki.24/.local/lib/python3.6/site-packages/sqlalchemy/pool/impl.py", line 146, in _do_get
    self._dec_overflow()
  File "/home/Liann.Bielicki.24/.local/lib/python3.6/site-packages/sqlalchemy/util/langhelpers.py", line 72, in __exit__
    with_traceback=exc_tb,
  File "/home/Liann.Bielicki.24/.local/lib/python3.6/site-packages/sqlalchemy/util/compat.py", line 211, in raise_
    raise exception
  File "/home/Liann.Bielicki.24/.local/lib/python3.6/site-packages/sqlalchemy/pool/impl.py", line 143, in _do_get
    return self._create_connection()
  File "/home/Liann.Bielicki.24/.local/lib/python3.6/site-packages/sqlalchemy/pool/base.py", line 273, in _create_connection
    return _ConnectionRecord(self)
  File "/home/Liann.Bielicki.24/.local/lib/python3.6/site-packages/sqlalchemy/pool/base.py", line 388, in __init__
    self.__connect()
  File "/home/Liann.Bielicki.24/.local/lib/python3.6/site-packages/sqlalchemy/pool/base.py", line 691, in __connect
    pool.logger.debug("Error on connect(): %s", e)
  File "/home/Liann.Bielicki.24/.local/lib/python3.6/site-packages/sqlalchemy/util/langhelpers.py", line 72, in __exit__
    with_traceback=exc_tb,
  File "/home/Liann.Bielicki.24/.local/lib/python3.6/site-packages/sqlalchemy/util/compat.py", line 211, in raise_
    raise exception
  File "/home/Liann.Bielicki.24/.local/lib/python3.6/site-packages/sqlalchemy/pool/base.py", line 686, in __connect
    self.dbapi_connection = connection = pool._invoke_creator(self)
  File "/home/Liann.Bielicki.24/.local/lib/python3.6/site-packages/sqlalchemy/engine/create.py", line 574, in connect
    return dialect.connect(*cargs, **cparams)
  File "/home/Liann.Bielicki.24/.local/lib/python3.6/site-packages/sqlalchemy/engine/default.py", line 598, in connect
    return self.dbapi.connect(*cargs, **cparams)
  File "/home/Liann.Bielicki.24/.local/lib/python3.6/site-packages/psycopg2/__init__.py", line 122, in connect
    conn = _connect(dsn, connection_factory=connection_factory, **kwasync)
psycopg2.OperationalError: could not connect to server: Connection refused
	Is the server running on host "localhost" (127.0.0.1) and accepting
	TCP/IP connections on port 18438?


The above exception was the direct cause of the following exception:

Traceback (most recent call last):
  File "load_tweets_batch.py", line 414, in <module>
    connection = engine.connect()
  File "/home/Liann.Bielicki.24/.local/lib/python3.6/site-packages/sqlalchemy/engine/base.py", line 3325, in connect
    return self._connection_cls(self, close_with_result=close_with_result)
  File "/home/Liann.Bielicki.24/.local/lib/python3.6/site-packages/sqlalchemy/engine/base.py", line 96, in __init__
    else engine.raw_connection()
  File "/home/Liann.Bielicki.24/.local/lib/python3.6/site-packages/sqlalchemy/engine/base.py", line 3404, in raw_connection
    return self._wrap_pool_connect(self.pool.connect, _connection)
  File "/home/Liann.Bielicki.24/.local/lib/python3.6/site-packages/sqlalchemy/engine/base.py", line 3375, in _wrap_pool_connect
    e, dialect, self
  File "/home/Liann.Bielicki.24/.local/lib/python3.6/site-packages/sqlalchemy/engine/base.py", line 2209, in _handle_dbapi_exception_noconnection
    sqlalchemy_exception, with_traceback=exc_info[2], from_=e
  File "/home/Liann.Bielicki.24/.local/lib/python3.6/site-packages/sqlalchemy/util/compat.py", line 211, in raise_
    raise exception
  File "/home/Liann.Bielicki.24/.local/lib/python3.6/site-packages/sqlalchemy/engine/base.py", line 3371, in _wrap_pool_connect
    return fn()
  File "/home/Liann.Bielicki.24/.local/lib/python3.6/site-packages/sqlalchemy/pool/base.py", line 327, in connect
    return _ConnectionFairy._checkout(self)
  File "/home/Liann.Bielicki.24/.local/lib/python3.6/site-packages/sqlalchemy/pool/base.py", line 894, in _checkout
    fairy = _ConnectionRecord.checkout(pool)
  File "/home/Liann.Bielicki.24/.local/lib/python3.6/site-packages/sqlalchemy/pool/base.py", line 493, in checkout
    rec = pool._do_get()
  File "/home/Liann.Bielicki.24/.local/lib/python3.6/site-packages/sqlalchemy/pool/impl.py", line 146, in _do_get
    self._dec_overflow()
  File "/home/Liann.Bielicki.24/.local/lib/python3.6/site-packages/sqlalchemy/util/langhelpers.py", line 72, in __exit__
    with_traceback=exc_tb,
  File "/home/Liann.Bielicki.24/.local/lib/python3.6/site-packages/sqlalchemy/util/compat.py", line 211, in raise_
    raise exception
  File "/home/Liann.Bielicki.24/.local/lib/python3.6/site-packages/sqlalchemy/pool/impl.py", line 143, in _do_get
    return self._create_connection()
  File "/home/Liann.Bielicki.24/.local/lib/python3.6/site-packages/sqlalchemy/pool/base.py", line 273, in _create_connection
    return _ConnectionRecord(self)
  File "/home/Liann.Bielicki.24/.local/lib/python3.6/site-packages/sqlalchemy/pool/base.py", line 388, in __init__
    self.__connect()
  File "/home/Liann.Bielicki.24/.local/lib/python3.6/site-packages/sqlalchemy/pool/base.py", line 691, in __connect
    pool.logger.debug("Error on connect(): %s", e)
  File "/home/Liann.Bielicki.24/.local/lib/python3.6/site-packages/sqlalchemy/util/langhelpers.py", line 72, in __exit__
    with_traceback=exc_tb,
  File "/home/Liann.Bielicki.24/.local/lib/python3.6/site-packages/sqlalchemy/util/compat.py", line 211, in raise_
    raise exception
  File "/home/Liann.Bielicki.24/.local/lib/python3.6/site-packages/sqlalchemy/pool/base.py", line 686, in __connect
    self.dbapi_connection = connection = pool._invoke_creator(self)
  File "/home/Liann.Bielicki.24/.local/lib/python3.6/site-packages/sqlalchemy/engine/create.py", line 574, in connect
    return dialect.connect(*cargs, **cparams)
  File "/home/Liann.Bielicki.24/.local/lib/python3.6/site-packages/sqlalchemy/engine/default.py", line 598, in connect
    return self.dbapi.connect(*cargs, **cparams)
  File "/home/Liann.Bielicki.24/.local/lib/python3.6/site-packages/psycopg2/__init__.py", line 122, in connect
    conn = _connect(dsn, connection_factory=connection_factory, **kwasync)
sqlalchemy.exc.OperationalError: (psycopg2.OperationalError) could not connect to server: Connection refused
	Is the server running on host "localhost" (127.0.0.1) and accepting
	TCP/IP connections on port 18438?

(Background on this error at: https://sqlalche.me/e/14/e3q8)
Traceback (most recent call last):
  File "/home/Liann.Bielicki.24/.local/lib/python3.6/site-packages/sqlalchemy/engine/base.py", line 3371, in _wrap_pool_connect
    return fn()
  File "/home/Liann.Bielicki.24/.local/lib/python3.6/site-packages/sqlalchemy/pool/base.py", line 327, in connect
    return _ConnectionFairy._checkout(self)
  File "/home/Liann.Bielicki.24/.local/lib/python3.6/site-packages/sqlalchemy/pool/base.py", line 894, in _checkout
    fairy = _ConnectionRecord.checkout(pool)
  File "/home/Liann.Bielicki.24/.local/lib/python3.6/site-packages/sqlalchemy/pool/base.py", line 493, in checkout
    rec = pool._do_get()
  File "/home/Liann.Bielicki.24/.local/lib/python3.6/site-packages/sqlalchemy/pool/impl.py", line 146, in _do_get
    self._dec_overflow()
  File "/home/Liann.Bielicki.24/.local/lib/python3.6/site-packages/sqlalchemy/util/langhelpers.py", line 72, in __exit__
    with_traceback=exc_tb,
  File "/home/Liann.Bielicki.24/.local/lib/python3.6/site-packages/sqlalchemy/util/compat.py", line 211, in raise_
    raise exception
  File "/home/Liann.Bielicki.24/.local/lib/python3.6/site-packages/sqlalchemy/pool/impl.py", line 143, in _do_get
    return self._create_connection()
  File "/home/Liann.Bielicki.24/.local/lib/python3.6/site-packages/sqlalchemy/pool/base.py", line 273, in _create_connection
    return _ConnectionRecord(self)
  File "/home/Liann.Bielicki.24/.local/lib/python3.6/site-packages/sqlalchemy/pool/base.py", line 388, in __init__
    self.__connect()
  File "/home/Liann.Bielicki.24/.local/lib/python3.6/site-packages/sqlalchemy/pool/base.py", line 691, in __connect
    pool.logger.debug("Error on connect(): %s", e)
  File "/home/Liann.Bielicki.24/.local/lib/python3.6/site-packages/sqlalchemy/util/langhelpers.py", line 72, in __exit__
    with_traceback=exc_tb,
  File "/home/Liann.Bielicki.24/.local/lib/python3.6/site-packages/sqlalchemy/util/compat.py", line 211, in raise_
    raise exception
  File "/home/Liann.Bielicki.24/.local/lib/python3.6/site-packages/sqlalchemy/pool/base.py", line 686, in __connect
    self.dbapi_connection = connection = pool._invoke_creator(self)
  File "/home/Liann.Bielicki.24/.local/lib/python3.6/site-packages/sqlalchemy/engine/create.py", line 574, in connect
    return dialect.connect(*cargs, **cparams)
  File "/home/Liann.Bielicki.24/.local/lib/python3.6/site-packages/sqlalchemy/engine/default.py", line 598, in connect
    return self.dbapi.connect(*cargs, **cparams)
  File "/home/Liann.Bielicki.24/.local/lib/python3.6/site-packages/psycopg2/__init__.py", line 122, in connect
    conn = _connect(dsn, connection_factory=connection_factory, **kwasync)
psycopg2.OperationalError: could not connect to server: Connection refused
	Is the server running on host "localhost" (127.0.0.1) and accepting
	TCP/IP connections on port 18438?


The above exception was the direct cause of the following exception:

Traceback (most recent call last):
  File "load_tweets_batch.py", line 414, in <module>
    connection = engine.connect()
  File "/home/Liann.Bielicki.24/.local/lib/python3.6/site-packages/sqlalchemy/engine/base.py", line 3325, in connect
    return self._connection_cls(self, close_with_result=close_with_result)
  File "/home/Liann.Bielicki.24/.local/lib/python3.6/site-packages/sqlalchemy/engine/base.py", line 96, in __init__
    else engine.raw_connection()
  File "/home/Liann.Bielicki.24/.local/lib/python3.6/site-packages/sqlalchemy/engine/base.py", line 3404, in raw_connection
    return self._wrap_pool_connect(self.pool.connect, _connection)
  File "/home/Liann.Bielicki.24/.local/lib/python3.6/site-packages/sqlalchemy/engine/base.py", line 3375, in _wrap_pool_connect
    e, dialect, self
  File "/home/Liann.Bielicki.24/.local/lib/python3.6/site-packages/sqlalchemy/engine/base.py", line 2209, in _handle_dbapi_exception_noconnection
    sqlalchemy_exception, with_traceback=exc_info[2], from_=e
  File "/home/Liann.Bielicki.24/.local/lib/python3.6/site-packages/sqlalchemy/util/compat.py", line 211, in raise_
    raise exception
  File "/home/Liann.Bielicki.24/.local/lib/python3.6/site-packages/sqlalchemy/engine/base.py", line 3371, in _wrap_pool_connect
    return fn()
  File "/home/Liann.Bielicki.24/.local/lib/python3.6/site-packages/sqlalchemy/pool/base.py", line 327, in connect
    return _ConnectionFairy._checkout(self)
  File "/home/Liann.Bielicki.24/.local/lib/python3.6/site-packages/sqlalchemy/pool/base.py", line 894, in _checkout
    fairy = _ConnectionRecord.checkout(pool)
  File "/home/Liann.Bielicki.24/.local/lib/python3.6/site-packages/sqlalchemy/pool/base.py", line 493, in checkout
    rec = pool._do_get()
  File "/home/Liann.Bielicki.24/.local/lib/python3.6/site-packages/sqlalchemy/pool/impl.py", line 146, in _do_get
    self._dec_overflow()
  File "/home/Liann.Bielicki.24/.local/lib/python3.6/site-packages/sqlalchemy/util/langhelpers.py", line 72, in __exit__
    with_traceback=exc_tb,
  File "/home/Liann.Bielicki.24/.local/lib/python3.6/site-packages/sqlalchemy/util/compat.py", line 211, in raise_
    raise exception
  File "/home/Liann.Bielicki.24/.local/lib/python3.6/site-packages/sqlalchemy/pool/impl.py", line 143, in _do_get
    return self._create_connection()
  File "/home/Liann.Bielicki.24/.local/lib/python3.6/site-packages/sqlalchemy/pool/base.py", line 273, in _create_connection
    return _ConnectionRecord(self)
  File "/home/Liann.Bielicki.24/.local/lib/python3.6/site-packages/sqlalchemy/pool/base.py", line 388, in __init__
    self.__connect()
  File "/home/Liann.Bielicki.24/.local/lib/python3.6/site-packages/sqlalchemy/pool/base.py", line 691, in __connect
    pool.logger.debug("Error on connect(): %s", e)
  File "/home/Liann.Bielicki.24/.local/lib/python3.6/site-packages/sqlalchemy/util/langhelpers.py", line 72, in __exit__
    with_traceback=exc_tb,
  File "/home/Liann.Bielicki.24/.local/lib/python3.6/site-packages/sqlalchemy/util/compat.py", line 211, in raise_
    raise exception
  File "/home/Liann.Bielicki.24/.local/lib/python3.6/site-packages/sqlalchemy/pool/base.py", line 686, in __connect
    self.dbapi_connection = connection = pool._invoke_creator(self)
  File "/home/Liann.Bielicki.24/.local/lib/python3.6/site-packages/sqlalchemy/engine/create.py", line 574, in connect
    return dialect.connect(*cargs, **cparams)
  File "/home/Liann.Bielicki.24/.local/lib/python3.6/site-packages/sqlalchemy/engine/default.py", line 598, in connect
    return self.dbapi.connect(*cargs, **cparams)
  File "/home/Liann.Bielicki.24/.local/lib/python3.6/site-packages/psycopg2/__init__.py", line 122, in connect
    conn = _connect(dsn, connection_factory=connection_factory, **kwasync)
sqlalchemy.exc.OperationalError: (psycopg2.OperationalError) could not connect to server: Connection refused
	Is the server running on host "localhost" (127.0.0.1) and accepting
	TCP/IP connections on port 18438?

(Background on this error at: https://sqlalche.me/e/14/e3q8)
Traceback (most recent call last):
  File "/home/Liann.Bielicki.24/.local/lib/python3.6/site-packages/sqlalchemy/engine/base.py", line 3371, in _wrap_pool_connect
    return fn()
  File "/home/Liann.Bielicki.24/.local/lib/python3.6/site-packages/sqlalchemy/pool/base.py", line 327, in connect
    return _ConnectionFairy._checkout(self)
  File "/home/Liann.Bielicki.24/.local/lib/python3.6/site-packages/sqlalchemy/pool/base.py", line 894, in _checkout
    fairy = _ConnectionRecord.checkout(pool)
  File "/home/Liann.Bielicki.24/.local/lib/python3.6/site-packages/sqlalchemy/pool/base.py", line 493, in checkout
    rec = pool._do_get()
  File "/home/Liann.Bielicki.24/.local/lib/python3.6/site-packages/sqlalchemy/pool/impl.py", line 146, in _do_get
    self._dec_overflow()
  File "/home/Liann.Bielicki.24/.local/lib/python3.6/site-packages/sqlalchemy/util/langhelpers.py", line 72, in __exit__
    with_traceback=exc_tb,
  File "/home/Liann.Bielicki.24/.local/lib/python3.6/site-packages/sqlalchemy/util/compat.py", line 211, in raise_
    raise exception
  File "/home/Liann.Bielicki.24/.local/lib/python3.6/site-packages/sqlalchemy/pool/impl.py", line 143, in _do_get
    return self._create_connection()
  File "/home/Liann.Bielicki.24/.local/lib/python3.6/site-packages/sqlalchemy/pool/base.py", line 273, in _create_connection
    return _ConnectionRecord(self)
  File "/home/Liann.Bielicki.24/.local/lib/python3.6/site-packages/sqlalchemy/pool/base.py", line 388, in __init__
    self.__connect()
  File "/home/Liann.Bielicki.24/.local/lib/python3.6/site-packages/sqlalchemy/pool/base.py", line 691, in __connect
    pool.logger.debug("Error on connect(): %s", e)
  File "/home/Liann.Bielicki.24/.local/lib/python3.6/site-packages/sqlalchemy/util/langhelpers.py", line 72, in __exit__
    with_traceback=exc_tb,
  File "/home/Liann.Bielicki.24/.local/lib/python3.6/site-packages/sqlalchemy/util/compat.py", line 211, in raise_
    raise exception
  File "/home/Liann.Bielicki.24/.local/lib/python3.6/site-packages/sqlalchemy/pool/base.py", line 686, in __connect
    self.dbapi_connection = connection = pool._invoke_creator(self)
  File "/home/Liann.Bielicki.24/.local/lib/python3.6/site-packages/sqlalchemy/engine/create.py", line 574, in connect
    return dialect.connect(*cargs, **cparams)
  File "/home/Liann.Bielicki.24/.local/lib/python3.6/site-packages/sqlalchemy/engine/default.py", line 598, in connect
    return self.dbapi.connect(*cargs, **cparams)
  File "/home/Liann.Bielicki.24/.local/lib/python3.6/site-packages/psycopg2/__init__.py", line 122, in connect
    conn = _connect(dsn, connection_factory=connection_factory, **kwasync)
psycopg2.OperationalError: could not connect to server: Connection refused
	Is the server running on host "localhost" (127.0.0.1) and accepting
	TCP/IP connections on port 18438?


The above exception was the direct cause of the following exception:

Traceback (most recent call last):
  File "load_tweets_batch.py", line 414, in <module>
    connection = engine.connect()
  File "/home/Liann.Bielicki.24/.local/lib/python3.6/site-packages/sqlalchemy/engine/base.py", line 3325, in connect
    return self._connection_cls(self, close_with_result=close_with_result)
  File "/home/Liann.Bielicki.24/.local/lib/python3.6/site-packages/sqlalchemy/engine/base.py", line 96, in __init__
    else engine.raw_connection()
  File "/home/Liann.Bielicki.24/.local/lib/python3.6/site-packages/sqlalchemy/engine/base.py", line 3404, in raw_connection
    return self._wrap_pool_connect(self.pool.connect, _connection)
  File "/home/Liann.Bielicki.24/.local/lib/python3.6/site-packages/sqlalchemy/engine/base.py", line 3375, in _wrap_pool_connect
    e, dialect, self
  File "/home/Liann.Bielicki.24/.local/lib/python3.6/site-packages/sqlalchemy/engine/base.py", line 2209, in _handle_dbapi_exception_noconnection
    sqlalchemy_exception, with_traceback=exc_info[2], from_=e
  File "/home/Liann.Bielicki.24/.local/lib/python3.6/site-packages/sqlalchemy/util/compat.py", line 211, in raise_
    raise exception
  File "/home/Liann.Bielicki.24/.local/lib/python3.6/site-packages/sqlalchemy/engine/base.py", line 3371, in _wrap_pool_connect
    return fn()
  File "/home/Liann.Bielicki.24/.local/lib/python3.6/site-packages/sqlalchemy/pool/base.py", line 327, in connect
    return _ConnectionFairy._checkout(self)
  File "/home/Liann.Bielicki.24/.local/lib/python3.6/site-packages/sqlalchemy/pool/base.py", line 894, in _checkout
    fairy = _ConnectionRecord.checkout(pool)
  File "/home/Liann.Bielicki.24/.local/lib/python3.6/site-packages/sqlalchemy/pool/base.py", line 493, in checkout
    rec = pool._do_get()
  File "/home/Liann.Bielicki.24/.local/lib/python3.6/site-packages/sqlalchemy/pool/impl.py", line 146, in _do_get
    self._dec_overflow()
  File "/home/Liann.Bielicki.24/.local/lib/python3.6/site-packages/sqlalchemy/util/langhelpers.py", line 72, in __exit__
    with_traceback=exc_tb,
  File "/home/Liann.Bielicki.24/.local/lib/python3.6/site-packages/sqlalchemy/util/compat.py", line 211, in raise_
    raise exception
  File "/home/Liann.Bielicki.24/.local/lib/python3.6/site-packages/sqlalchemy/pool/impl.py", line 143, in _do_get
    return self._create_connection()
  File "/home/Liann.Bielicki.24/.local/lib/python3.6/site-packages/sqlalchemy/pool/base.py", line 273, in _create_connection
    return _ConnectionRecord(self)
  File "/home/Liann.Bielicki.24/.local/lib/python3.6/site-packages/sqlalchemy/pool/base.py", line 388, in __init__
    self.__connect()
  File "/home/Liann.Bielicki.24/.local/lib/python3.6/site-packages/sqlalchemy/pool/base.py", line 691, in __connect
    pool.logger.debug("Error on connect(): %s", e)
  File "/home/Liann.Bielicki.24/.local/lib/python3.6/site-packages/sqlalchemy/util/langhelpers.py", line 72, in __exit__
    with_traceback=exc_tb,
  File "/home/Liann.Bielicki.24/.local/lib/python3.6/site-packages/sqlalchemy/util/compat.py", line 211, in raise_
    raise exception
  File "/home/Liann.Bielicki.24/.local/lib/python3.6/site-packages/sqlalchemy/pool/base.py", line 686, in __connect
    self.dbapi_connection = connection = pool._invoke_creator(self)
  File "/home/Liann.Bielicki.24/.local/lib/python3.6/site-packages/sqlalchemy/engine/create.py", line 574, in connect
    return dialect.connect(*cargs, **cparams)
  File "/home/Liann.Bielicki.24/.local/lib/python3.6/site-packages/sqlalchemy/engine/default.py", line 598, in connect
    return self.dbapi.connect(*cargs, **cparams)
  File "/home/Liann.Bielicki.24/.local/lib/python3.6/site-packages/psycopg2/__init__.py", line 122, in connect
    conn = _connect(dsn, connection_factory=connection_factory, **kwasync)
sqlalchemy.exc.OperationalError: (psycopg2.OperationalError) could not connect to server: Connection refused
	Is the server running on host "localhost" (127.0.0.1) and accepting
	TCP/IP connections on port 18438?

(Background on this error at: https://sqlalche.me/e/14/e3q8)
Traceback (most recent call last):
  File "/home/Liann.Bielicki.24/.local/lib/python3.6/site-packages/sqlalchemy/engine/base.py", line 3371, in _wrap_pool_connect
    return fn()
  File "/home/Liann.Bielicki.24/.local/lib/python3.6/site-packages/sqlalchemy/pool/base.py", line 327, in connect
    return _ConnectionFairy._checkout(self)
  File "/home/Liann.Bielicki.24/.local/lib/python3.6/site-packages/sqlalchemy/pool/base.py", line 894, in _checkout
    fairy = _ConnectionRecord.checkout(pool)
  File "/home/Liann.Bielicki.24/.local/lib/python3.6/site-packages/sqlalchemy/pool/base.py", line 493, in checkout
    rec = pool._do_get()
  File "/home/Liann.Bielicki.24/.local/lib/python3.6/site-packages/sqlalchemy/pool/impl.py", line 146, in _do_get
    self._dec_overflow()
  File "/home/Liann.Bielicki.24/.local/lib/python3.6/site-packages/sqlalchemy/util/langhelpers.py", line 72, in __exit__
    with_traceback=exc_tb,
  File "/home/Liann.Bielicki.24/.local/lib/python3.6/site-packages/sqlalchemy/util/compat.py", line 211, in raise_
    raise exception
  File "/home/Liann.Bielicki.24/.local/lib/python3.6/site-packages/sqlalchemy/pool/impl.py", line 143, in _do_get
    return self._create_connection()
  File "/home/Liann.Bielicki.24/.local/lib/python3.6/site-packages/sqlalchemy/pool/base.py", line 273, in _create_connection
    return _ConnectionRecord(self)
  File "/home/Liann.Bielicki.24/.local/lib/python3.6/site-packages/sqlalchemy/pool/base.py", line 388, in __init__
    self.__connect()
  File "/home/Liann.Bielicki.24/.local/lib/python3.6/site-packages/sqlalchemy/pool/base.py", line 691, in __connect
    pool.logger.debug("Error on connect(): %s", e)
  File "/home/Liann.Bielicki.24/.local/lib/python3.6/site-packages/sqlalchemy/util/langhelpers.py", line 72, in __exit__
    with_traceback=exc_tb,
  File "/home/Liann.Bielicki.24/.local/lib/python3.6/site-packages/sqlalchemy/util/compat.py", line 211, in raise_
    raise exception
  File "/home/Liann.Bielicki.24/.local/lib/python3.6/site-packages/sqlalchemy/pool/base.py", line 686, in __connect
    self.dbapi_connection = connection = pool._invoke_creator(self)
  File "/home/Liann.Bielicki.24/.local/lib/python3.6/site-packages/sqlalchemy/engine/create.py", line 574, in connect
    return dialect.connect(*cargs, **cparams)
  File "/home/Liann.Bielicki.24/.local/lib/python3.6/site-packages/sqlalchemy/engine/default.py", line 598, in connect
    return self.dbapi.connect(*cargs, **cparams)
  File "/home/Liann.Bielicki.24/.local/lib/python3.6/site-packages/psycopg2/__init__.py", line 122, in connect
    conn = _connect(dsn, connection_factory=connection_factory, **kwasync)
psycopg2.OperationalError: could not connect to server: Connection refused
	Is the server running on host "localhost" (127.0.0.1) and accepting
	TCP/IP connections on port 18438?


The above exception was the direct cause of the following exception:

Traceback (most recent call last):
  File "load_tweets_batch.py", line 414, in <module>
    connection = engine.connect()
  File "/home/Liann.Bielicki.24/.local/lib/python3.6/site-packages/sqlalchemy/engine/base.py", line 3325, in connect
    return self._connection_cls(self, close_with_result=close_with_result)
  File "/home/Liann.Bielicki.24/.local/lib/python3.6/site-packages/sqlalchemy/engine/base.py", line 96, in __init__
    else engine.raw_connection()
  File "/home/Liann.Bielicki.24/.local/lib/python3.6/site-packages/sqlalchemy/engine/base.py", line 3404, in raw_connection
    return self._wrap_pool_connect(self.pool.connect, _connection)
  File "/home/Liann.Bielicki.24/.local/lib/python3.6/site-packages/sqlalchemy/engine/base.py", line 3375, in _wrap_pool_connect
    e, dialect, self
  File "/home/Liann.Bielicki.24/.local/lib/python3.6/site-packages/sqlalchemy/engine/base.py", line 2209, in _handle_dbapi_exception_noconnection
    sqlalchemy_exception, with_traceback=exc_info[2], from_=e
  File "/home/Liann.Bielicki.24/.local/lib/python3.6/site-packages/sqlalchemy/util/compat.py", line 211, in raise_
    raise exception
  File "/home/Liann.Bielicki.24/.local/lib/python3.6/site-packages/sqlalchemy/engine/base.py", line 3371, in _wrap_pool_connect
    return fn()
  File "/home/Liann.Bielicki.24/.local/lib/python3.6/site-packages/sqlalchemy/pool/base.py", line 327, in connect
    return _ConnectionFairy._checkout(self)
  File "/home/Liann.Bielicki.24/.local/lib/python3.6/site-packages/sqlalchemy/pool/base.py", line 894, in _checkout
    fairy = _ConnectionRecord.checkout(pool)
  File "/home/Liann.Bielicki.24/.local/lib/python3.6/site-packages/sqlalchemy/pool/base.py", line 493, in checkout
    rec = pool._do_get()
  File "/home/Liann.Bielicki.24/.local/lib/python3.6/site-packages/sqlalchemy/pool/impl.py", line 146, in _do_get
    self._dec_overflow()
  File "/home/Liann.Bielicki.24/.local/lib/python3.6/site-packages/sqlalchemy/util/langhelpers.py", line 72, in __exit__
    with_traceback=exc_tb,
  File "/home/Liann.Bielicki.24/.local/lib/python3.6/site-packages/sqlalchemy/util/compat.py", line 211, in raise_
    raise exception
  File "/home/Liann.Bielicki.24/.local/lib/python3.6/site-packages/sqlalchemy/pool/impl.py", line 143, in _do_get
    return self._create_connection()
  File "/home/Liann.Bielicki.24/.local/lib/python3.6/site-packages/sqlalchemy/pool/base.py", line 273, in _create_connection
    return _ConnectionRecord(self)
  File "/home/Liann.Bielicki.24/.local/lib/python3.6/site-packages/sqlalchemy/pool/base.py", line 388, in __init__
    self.__connect()
  File "/home/Liann.Bielicki.24/.local/lib/python3.6/site-packages/sqlalchemy/pool/base.py", line 691, in __connect
    pool.logger.debug("Error on connect(): %s", e)
  File "/home/Liann.Bielicki.24/.local/lib/python3.6/site-packages/sqlalchemy/util/langhelpers.py", line 72, in __exit__
    with_traceback=exc_tb,
  File "/home/Liann.Bielicki.24/.local/lib/python3.6/site-packages/sqlalchemy/util/compat.py", line 211, in raise_
    raise exception
  File "/home/Liann.Bielicki.24/.local/lib/python3.6/site-packages/sqlalchemy/pool/base.py", line 686, in __connect
    self.dbapi_connection = connection = pool._invoke_creator(self)
  File "/home/Liann.Bielicki.24/.local/lib/python3.6/site-packages/sqlalchemy/engine/create.py", line 574, in connect
    return dialect.connect(*cargs, **cparams)
  File "/home/Liann.Bielicki.24/.local/lib/python3.6/site-packages/sqlalchemy/engine/default.py", line 598, in connect
    return self.dbapi.connect(*cargs, **cparams)
  File "/home/Liann.Bielicki.24/.local/lib/python3.6/site-packages/psycopg2/__init__.py", line 122, in connect
    conn = _connect(dsn, connection_factory=connection_factory, **kwasync)
sqlalchemy.exc.OperationalError: (psycopg2.OperationalError) could not connect to server: Connection refused
	Is the server running on host "localhost" (127.0.0.1) and accepting
	TCP/IP connections on port 18438?

(Background on this error at: https://sqlalche.me/e/14/e3q8)
Command exited with non-zero status 10
3.76user 0.53system 0:00.74elapsed 575%CPU (0avgtext+0avgdata 42684maxresident)k
40inputs+2488outputs (0major+158007minor)pagefaults 0swaps
